Workbook

Sheet MASTER
A1: NO | G1: AKTA KELAHIRAN | H1: TANGGAL DITERIMA | I1: ASAL PESERTA DIDIK | J1: NAMA TK ASAL | K1: ALAMAT TK ASAL | L1: NOMOR/TANGGAL STTB | M1: NIS | N1: NISN | O1: NO KK | P1: NIK ANAK | Q1: NAMA SISWA (sesuai Akta Kelahiran) | R1: GRADE | S1: CLASS NAME | T1: NAMA PANGGILAN | U1: SEX | V1: TEMPAT LAHIR | W1: TANGGAL LAHIR | X1: USIA | Y1: JENIS PESERTA DIDIK | Z1: JENIS KETUNAAN | AA1: AGAMA | AB1: KEWARGANEGARAAN | AC1: ALAMAT RUMAH | AD1: RT | AE1: RW | AF1: KELURAHAN | AG1: KECAMATAN | AH1: SEBARAN KECAMATAN PESERTA DIDIK SD ANAK SALEH | AI1: KODE POS | AJ1: KABUPATEN/KOTA | AK1: STATUS TEMPAT TINGGAL | AL1: JARAK TEMPAT TINGGAL KE SEKOLAH | AM1: NO. TELEPON RUMAH | AN1: NO. HANDPHONE | AO1: ANAK KE | AP1: ∑ SAUDARA KANDUNG | AQ1: ∑ SAUDARA TIRI | AR1: ∑ SAUDARA ANGKAT | AS1: BB | AT1: TB | AU1: GOL DARAH | AV1: PENYAKIT BERAT YANG PERNAH DIDERITA | AW1: PENYAKIT YANG SERING DIDERITA | AX1: BAHASA KESEHARIAN DI KELUARGA | AY1: NAMA AYAH KANDUNG | AZ1: NIK AYAH | BA1: TEMPAT LAHIR AYAH | BB1: TANGGAL LAHIR AYAH | BC1: AGAMA AYAH | BD1: NO. HANDPHONE AYAH | BE1: PENDIDIKAN TERTINGGI AYAH | BF1: PEKERJAAN AYAH | BG1: INSTANSI TEMPAT BEKERJA AYAH | BH1: ALAMAT LENGKAP INSTANSI AYAH | BI1: NO. TELEPON INSTANSI AYAH | BJ1: PENGHASILAN AYAH PER BULAN | BK1: EMAIL AYAH | BL1: NAMA IBU KANDUNG | BM1: NIK IBU | BN1: TEMPAT LAHIR IBU | BO1: TANGGAL LAHIR IBU | BP1: AGAMA IBU | BQ1: NO. HANDPHONE IBU | BR1: PENDIDIKAN TERTINGGI IBU | BS1: PEKERJAAN IBU | BT1: INSTANSI TEMPAT BEKERJA IBU | BU1: ALAMAT LENGKAP INSTANSI IBU | BV1: NO. TELEPON INSTANSI IBU | BW1: PENGHASILAN IBU PER BULAN | BX1: EMAIL IBU | BY1: NAMA WALI | BZ1: TEMPAT LAHIR WALI | CA1: TANGGAL LAHIR WALI | CB1: HUBUNGAN KELUARGA DENGAN WALI | CC1: NO. HANDPHONE WALI | CD1: PENDIDIKAN TERAKHIR WALI | CE1: PEKERJAAN WALI | CF1: AGAMA WALI | CG1: ALAMAT RUMAH WALI | CH1: RT | CI1: RW | CJ1: KELURAHAN | CK1: KECAMATAN | CL1: KABUPATEN/KOTA
B2: AKTE | C2: KK | D2: SUKET TK | E2: SURAT <6 TH | F2: SURAT PDBK
A3: 80 | I3: TAMAN KANAK-KANAK (TK) | J3: TK AKADEMIKA AL-ARSYAD | K3: PERUM GRIYA PERMATA ALAM JL. PINUS NGIJO KARANGPLOSO | M3: 2225 | N3: 3203452844 | O3: 3507232603150004 | P3: 3507232006200001 | Q3: AHMAD RISKI BAIHAQI | R3: 1A | S3: BERLIAN | T3: HAQI | U3: LAKI-LAKI | V3: MALANG | W3: 44002 | Y3: REGULER | AA3: ISLAM | AB3: WARGA NEGARA INDONESIA | AC3: PERUM PALM REGENCY KAV66 NGIJO KARANGPLOSO | AD3: 08 | AE3: 08 | AF3: NGIJO | AG3: KARANGPLOSO | AH3: LUAR MALANG | AI3: 65152 | AJ3: MALANG | AM3: 081252596006 | AN3: 085784005656 | AO3: 1 | AP3: 0 | AS3: 15 | AT3: 101 | AV3: TIDAK | AW3: BATUK, PILEK | AX3: JAWA/INDONESIA | AY3: FAHMI EFENDI YUSUF | AZ3: 3507230805890001 | BA3: MALANG | BB3: 32636 | BC3: ISLAM | BD3: 081252596006 | BE3: S2 | BF3: WIRASWASTA | BG3: PT ELECTRINDO INTI NUSANTARA | BH3: PERUM GRAHA KENCANA RAYA NO 26-28 BALEARJOSARI | BJ3: 10000000 | BK3: fahmiefendiy@gmail.com | BL3: WIWIT INDAWATI | BM3: 3507236402960001 | BN3: MALANG | BO3: 35119 | BP3: ISLAM | BQ3: 085784005656 | BR3: SMA/SMK SEDERAJAT | BS3: IBU RUMAH TANGGA | BT3: - | BU3: - | BV3: - | BW3: - | BX3: wiwitindawati1122@gmail.com | BY3: FAHMI EFENDI YUSUF | BZ3: MALANG | CA3: 32636 | CC3: 081252596006 | CD3: S2 | CE3: WIRASWASTA
A4: 54 | I4: TAMAN KANAK-KANAK (TK) | J4: KB-TK ISLAM KHARISMA MALANG | K4: TIRTASANI ROYAL RESORT BLOK F2 8-9 | M4: 2226 | N4: 3203464357 | O4: 3573011010170029 | P4: 3573014306200005 | Q4: AISHA SHEZA IZDIHAR LAKSANA | R4: 1A | S4: BERLIAN | T4: AISH | U4: PEREMPUAN | V4: MALANG | W4: 43985 | Y4: REGULER | AA4: ISLAM | AB4: WARGA NEGARA INDONESIA | AC4: PERUM TIRTASANI ROYAL RESORT, CLUSTER ROYAL VILLAGE BLOK RV3 NO 3 | AD4: 06 | AE4: 16 | AF4: NGENEP | AG4: KARANGPLOSO | AH4: LUAR MALANG | AI4: 65152 | AJ4: MALANG | AM4: 081944893272 | AN4: 081944893272 | AO4: 2 | AP4: 1 | AS4: 15 | AT4: 100 | AV4: TIDAK | AW4: DEMAM, BATUK | AX4: BAHASA INDONESIA | AY4: Elfa Rizal Dwi Laksono, S.Ap | AZ4: 3507241405890003 | BA4: MALANG | BB4: 32642 | BC4: ISLAM | BD4: 081808901737 | BE4: S1 | BF4: KARYAWAN SWASTA | BG4: PT AMCOR SPECIALTY CARTONS INDONESIA | BH4: JL. REMBANG INDUSTRI RAYA NO.36, JATI, PANDEAN, KEC. REMBANG, PASURUAN, JAWA TIMUR 67152 | BJ4: - | BK4: - | BL4: Arnita Eka Wulandari, S.ST | BM4: 3573014908900008 | BN4: BOJONEGORO | BO4: 33094 | BP4: ISLAM | BQ4: 081944893272 | BR4: S1 | BS4: KARYAWAN SWASTA | BT4: PT KILAP GLOBAL GROUP | BU4: GRIYA SHANTA BLK. J NO.298-299, MOJOLANGU, KEC. LOWOKWARU, KOTA MALANG, JAWA TIMUR 65142 | BW4: 5.000.000 | BX4: arnitaekawulandari90@gmail.com
A5: 34 | I5: RAUDHATUL ATHFAL (RA) | J5: RA AMAL MULIA DEPOK | K5: JALAN PEKAPURAN DEPOK | M5: 2228 | N5: 3194677510 | O5: 3276102910180004 | P5: 3276106207190002 | Q5: AIZA SHAKEENA RIKZATUNNISA | R5: 1A | S5: BERLIAN | T5: AIZA | U5: PEREMPUAN | V5: MALANG | W5: 43668 | Y5: REGULER | AA5: ISLAM | AB5: WARGA NEGARA INDONESIA | AC5: JALAN MAWAR 4 NO. 27 | AD5: 06 | AE5: 04 | AF5: LOWOKWARU | AG5: LOWOKWARU | AH5: LOWOKWARU | AI5: 65141 | AJ5: MALANG | AM5: - | AN5: 081288319704 | AO5: 1 | AP5: 1 | AS5: 21 | AT5: 110 | AV5: TIDAK | AW5: DEMAM, BATUK, PILEK | AX5: BAHASA INDONESIA | AY5: Andika Risma Pratama, A.Md | AZ5: 3276020508910001 | BA5: BOGOR | BB5: 33455 | BC5: ISLAM | BD5: 081288319704 | BE5: S1 | BF5: KARYAWAN SWASTA | BG5: PT. SAPTA INDERA SEJATI | BH5: GD. GRAHA SAPTAINDRA, JL. TB. SIMATUPANG KAV. 18, CILANDAK BARAT, JAKARTA SELATAN, DKI JAKARTA 12430 | BI5: - | BJ5: 15.000.000 | BK5: 08andika@gmail.com | BL5: Lia Rizqimawati, A.Md | BM5: 3573056903950005 | BN5: MALANG | BO5: 34787 | BP5: ISLAM | BQ5: 082234719535 | BR5: S1 | BS5: IBU RUMAH TANGGA | BT5: - | BU5: - | BV5: - | BW5: - | BX5: liarizqi293@gmail.com | BY5: Lia Permatasari, S.T | BZ5: MALANG | CA5: 37295 | CC5: 082132519606 | CD5: S1 | CE5: -
A6: 8 | I6: TAMAN KANAK-KANAK (TK) | J6: PERMATA IMAN 1 | K6: JL. BATU PERMATA 9, TLOGOMAS, MALANG | M6: 2231 | N6: 3196274753 | O6: 3507220907190005 | P6: 3507222707190001 | Q6: ALDEBARAN ARSENIO MUHAMMAD | R6: 1A | S6: BERLIAN | T6: BARAN | U6: LAKI-LAKI | V6: MALANG | W6: 43673 | Y6: REGULER | AA6: ISLAM | AB6: WARGA NEGARA INDONESIA | AC6: LANDUNGSARI PERMAI C-2 | AD6: 1 | AE6: 6 | AF6: LANDUNGSARI | AG6: DAU | AH6: LUAR MALANG | AI6: 65151 | AJ6: MALANG | AM6: - | AN6: 085156428643 | AO6: 1 | AP6: 0 | AS6: 20 | AT6: 110 | AV6: TIDAK | AW6: BATUK, PILEK | AX6: INDONESIA | AY6: Rheza Febrian Putranto, S.T | AZ6: 35072221002970001 | BA6: MALANG | BB6: 35471 | BC6: ISLAM | BD6: 081233663741 | BE6: S1 | BF6: KARYAWAN SWASTA | BG6: PT. DELTA UTRACON SYNERGY | BH6: GD. WISMA RITRA, JI. BUNCIT RAYA NO.6 LT.2, RT.1/RW.9, KALIBATA, KEC. PANCORAN, KOTA JAKARTA SELATAN, DAERAH KHUSUS IBUKOTA JAKARTA 12740 | BI6: (021) 7970827 | BJ6: 11 jt | BK6: Febrianrheza@gmail.com | BL6: Silmi Mauludina, S.PWK | BM6: 3578085607980001 | BN6: SURABAYA | BO6: 35992 | BP6: ISLAM | BQ6: 085156428643 | BR6: S1 | BS6: KARYAWAN SWASTA | BT6: POLRESTA MALANG KOTA | BU6: JL. JAKSA AGUNG SUPRAPTO 19 | BV6: - | BW6: 1.500.000 | BX6: Silmimauludina.contact@gmail.com
A7: 89 | I7: BUSTHANUL ATHFAL (BA) | J7: KB - BA ARAFAH | K7: JL. VINOLIA III NO 23 | M7: 2239 | N7: 3195767578 | O7: 3573051803190007 | P7: 3573052106190003 | Q7: AMMAR RHEANDRA PRATAMA | R7: 1A | S7: BERLIAN | T7: AMMAR | U7: LAKI-LAKI | V7: MALANG | W7: 43637 | Y7: REGULER | AA7: ISLAM | AB7: WARGA NEGARA INDONESIA | AC7: PERUM GARDEN PALMA BLOK A2 | AD7: 007 | AE7: 005 | AF7: JATIMULYO | AG7: LOWOKWARU | AH7: LOWOKWARU | AI7: 65141 | AJ7: MALANG | AM7: 081252536008 | AN7: 081252536008 | AO7: 1 | AP7: 1 | AS7: 18 | AT7: 116 | AV7: TIDAK | AW7: Tidak ada | AX7: INDONESIA | AY7: Drh. Awang Yoga Pratama | AZ7: 3525100708900001 | BA7: GRESIK | BB7: 33092 | BC7: ISLAM | BD7: 081217399685 | BE7: S1 | BF7: KARYAWAN SWASTA | BG7: PT. ANDROMEDA GROUP | BH7: JL. CILIWUNG NO.74C, DARMO, KEC. WONOKROMO, SURABAYA, JAWA TIMUR 60241 | BI7: (031) 58282876 | BJ7: 10.000.000 | BK7: awangyogapratama7890@gmail.com | BL7: Drh. Romdhani Retno Fatwa | BM7: 3509125703930002 | BN7: JEMBER | BO7: 34045 | BP7: ISLAM | BQ7: 081252536008 | BR7: S1 | BS7: MENGURUS RUMAH TANGGA | BT7: - | BU7: - | BV7: - | BW7: - | BX7: romdhaniretno@gmail.com
A8: 68 | I8: TAMAN KANAK-KANAK (TK) | J8: TK ANAK SALEH | K8: JL CANDI PANGGUNG INDAH | M8: 2255 | N8: 3185561643 | O8: 3507231402180010 | P8: 3507230512180004 | Q8: DEVA ABI PUTRA | R8: 1A | S8: BERLIAN | T8: DEVA | U8: LAKI-LAKI | V8: BANYUWANGI | W8: 43439 | Y8: PDBK (BERKEBUTUHAN KHUSUS) | Z8: Asd level1 high function | AA8: ISLAM | AB8: WARGA NEGARA INDONESIA | AC8: GRAND PERMATA JINGGA 8TH NO15 | AD8: 01 | AE8: 21 | AF8: MANGLIAWAN | AG8: PAKIS | AH8: LUAR MALANG | AI8: 65153 | AJ8: MALANG | AM8: 0 | AN8: 085746730392 | AO8: 1 | AP8: 2 | AS8: 19 | AT8: 110 | AV8: TIDAK | AW8: BATUK | AX8: INDONESIA | AY8: Deby Putra Bahrodin S.Si | AZ8: 3507011304920001 | BA8: MALANG | BB8: 33707 | BC8: ISLAM | BD8: 085646300333 | BE8: S1 | BF8: SOFTWARE HOUSE AND TELCO | BG8: - | BH8: - | BI8: - | BJ8: 10.000.000-30.000.000 | BK8: deby.putra@gmail.com | BL8: Eva Rosalina | BM8: 3510085205930002 | BN8: BANYUWANGI | BO8: 34101 | BP8: ISLAM | BQ8: 085746730392 | BR8: S1 | BS8: IBU RUMAH TANGGA | BT8: - | BU8: - | BV8: - | BW8: - | BX8: evarosalina1205@gmail.com
A9: 6 | I9: TAMAN KANAK-KANAK (TK) | J9: TK ANAK SALEH | K9: JL. CANDI PANGGUNG INDAH NO.1-3, KELURAHAN MOJOLANGU | M9: 2258 | N9: 3208549116 | O9: 3573053001200009 | P9: 3573052302200001 | Q9: FEBRINO YUSUF SYAILENDRA PRATAMA | R9: 1A | S9: BERLIAN | T9: RINO | U9: LAKI-LAKI | V9: MALANG | W9: 43884 | Y9: REGULER | AA9: ISLAM | AB9: WARGA NEGARA INDONESIA | AC9: GARDEN PALMA INSIDE KAV. 2 | AD9: 004 | AE9: 009 | AF9: MOJOLANGU | AG9: LOWOKWARU | AH9: LOWOKWARU | AI9: 65142 | AJ9: KOTA MALANG | AM9: 083857954344 | AN9: 083857954344 | AO9: 1 | AP9: 0 | AS9: 22 | AT9: 120 | AV9: TIDAK | AW9: BATUK, PILEK | AX9: BAHASA INDONESIA | AY9: ANDY PRABOWO | AZ9: 3507243006970003 | BA9: TUBAN | BB9: 35611 | BC9: ISLAM | BD9: 082232263062 | BE9: SMA/SMK SEDERAJAT | BF9: KARYAWAN SWASTA | BG9: PT. ASIANET MEDIA TEKNOLOGI | BH9: JALAN BUNGA COKLAT NO.4 KAV.1 KELURAHAN TULUSREJO KECAMATAN LOWOKWARU KOTA MALANG 65141 | BJ9: 4000000 | BK9: andyprabowo06@gmail.com | BL9: DINDA AYU JEAN ASTRY S.Ak | BM9: 3515185106970002 | BN9: SUMENEP | BO9: 35592 | BP9: ISLAM | BQ9: 083857954344 | BR9: S1 | BS9: IBU RUMAHTANGGA | BT9: - | BU9: - | BV9: - | BW9: - | BX9: dindajean11@gmail.com
A10: 11 | I10: TAMAN KANAK-KANAK (TK) | J10: TK ZAMZAM | K10: JALAN CAKALANG NO. 209A KEL. POLOWIJEN KEC. BLIMBING MALANG | M10: 2266 | N10: 3198173105 | O10: 3573020701200001 | P10: 3573024101190002 | Q10: HAYFA RIFKI ABDAT | R10: 1A | S10: BERLIAN | T10: HAYFA | U10: PEREMPUAN | V10: SIDOARJO | W10: 43466 | Y10: REGULER | AA10: ISLAM | AB10: WARGA NEGARA INDONESIA | AC10: RIVERSIDE D-312 | AD10: 02 | AE10: 05 | AF10: ARJOSARI | AG10: BLIMBING | AH10: BLIMBING | AI10: 65126 | AJ10: MALANG | AM10: D-312 | AN10: 081336469821 | AO10: 1 | AP10: 0 | AS10: 19 | AT10: 121 | AV10: TIDAK | AW10: Jarang | AX10: INDONESIA | AY10: Mochamad Rifki A. Md. AB., SE. | AZ10: 3573022901860001 | BA10: MALANG | BB10: 31441 | BC10: ISLAM | BD10: 081333713381 | BE10: S1 | BF10: WIRAUSAHA | BG10: UTAMA MOTOR | BH10: JALAN ANGGREK 3 DS. BAMBAN KEL. ASRIKATON KEC. PAKIS KAB. MALANG | BI10: 082139111193 | BJ10: 7.000.000 | BK10: rifkiarea86@gmail.com | BL10: Adiba | BM10: 3515076409940001 | BN10: LUMAJANG | BO10: 34601 | BP10: ISLAM | BQ10: 081336469821 | BR10: SMA/SMK SEDERAJAT | BS10: IBU RUMAH TANGGA | BT10: RUMAH | BU10: RIVERSIDE D-312 KEL. ARJOSARI KEC. BLIMBING MALANG | BW10: 3.000.000 | BX10: adiba24994@gmail.com
A11: 103 | I11: TAMAN KANAK-KANAK (TK) | J11: TK PERMATA IMAN 2 | K11: JL. IKAN KAKAP NO. 90 MALANG | M11: 2271 | N11: 3191576519 | O11: 3507232709130004 | P11: 3507231807190001 | Q11: JULIAN RAZKA TIRTA | R11: 1A | S11: BERLIAN | T11: TIRTA | U11: LAKI-LAKI | V11: MALANG | W11: 43664 | Y11: Reguler | Z11: Tidak | AA11: ISLAM | AB11: WARGA NEGARA INDONESIA | AC11: JL. PERTAMANAN 5 | AD11: 17 | AE11: 06 | AF11: KEPUHARJO | AG11: KARANGPLOSO | AH11: LUAR MALANG | AI11: 65152 | AJ11: MALANG | AN11: 083831568320 | AO11: 2 | AP11: 1 | AS11: 17 | AT11: 117 | AV11: TIDAK | AW11: Ada riwayat sakit lambung dan types | AX11: BAHASA INDONESIA DAN BAHASA JAWA | AY11: ACHMAD BAIDHOWI | AZ11: 3517122712860002 | BA11: JOMBANG | BB11: 31773 | BC11: ISLAM | BD11: 08563483597 | BE11: SMA/SMK SEDERAJAT | BF11: WIRAUSAHA | BG11: TOKO | BH11: JL. PASAR WISATA KEPUHARJO | BI11: 08563483597 | BJ11: 6.000.000 | BK11: maulanasabil58@gmail.com | BL11: KHUSNIATUL WAKHIDAH | BM11: 3507236012920001 | BN11: MALANG | BO11: 33958 | BP11: ISLAM | BQ11: 08383156832 | BR11: SMA/SMK SEDERAJAT | BS11: WIRAUSAHA | BT11: TOKO | BU11: JL. RAYA PASAR WISATA | BV11: 08563483597 | BW11: - | BX11: maulanasabil58@gmail.com
A12: 45 | I12: TAMAN KANAK-KANAK (TK) | J12: TK ANAK SALEH MALANG | K12: ALAMAT TK ANAK SALEH TERLETAK DI JL. CANDI PANGGUNG INDAH NO. 1-3, MOJOLANGU, KEC. LOWOKWARU, KOTA MALANG, JAWA TIMUR. | M12: 2278 | N12: 3198141575 | O12: 3573051404140003 | P12: 3573016510190002 | Q12: KYANAYYIRA FARIZA ARVI | R12: 1A | S12: BERLIAN | T12: FAZA | U12: PEREMPUAN | V12: MALANG | W12: 43763 | Y12: REGULER | Z12: - | AA12: ISLAM | AB12: WARGA NEGARA INDONESIA | AC12: PELITA TELUK BAYUR E2 | AD12: 001 | AE12: 008 | AF12: PANDANWANGI | AG12: BLIMBING | AH12: BLIMBING | AI12: 65126 | AJ12: KOTA MALANG | AM12: - | AN12: 081233088233 | AO12: 2 | AP12: 2 | AS12: 18 | AT12: 115 CM | AV12: TIDAK | AW12: BATUK PILEK (JARANG) | AX12: INDONESIA | AY12: ARIEF RAKHMAD YASIN, S.T. | AZ12: 3573050906850003 | BA12: MALANG | BB12: 31207 | BC12: ISLAM | BD12: 081256985000 | BE12: S1 | BF12: PEGAWAI SWASTA | BG12: PT. SO GOOD FOOD | BH12: RUKO PD MASPION, JLN PD MASPION NO 7, PEPELEGI - WARU - SIDOARJO | BI12: - | BJ12: 10.000.000,- | BK12: arief.rakhmad@gmail.com | BL12: DEVI SETYA CHRISTINA, S.T. | BM12: 3573036308860004 | BN12: MALANG | BO12: 31647 | BP12: ISLAM | BQ12: 081233088233 | BR12: S1 | BS12: BLUD | BT12: RS DR. SAIFUL ANWAR MALANG | BU12: JL. JAKSA AGUNG SUPRAPTO 2, KOTA MALANG, JAWA TIMUR, 65111 | BV12: (0341) 362101 | BW12: 4.000.000,- | BX12: devi.setyac@gmail.com
A13: 47 | I13: TAMAN KANAK-KANAK (TK) | J13: KARTIKA PRADANA | K13: JL AKORDION TUNGGULWULUNG | M13: 2279 | N13: 3195065671 | O13: 3507232202180021 | P13: 3507232811190001 | Q13: MAHER | R13: 1A | S13: BERLIAN | T13: MAHER | U13: LAKI-LAKI | V13: MALANG | W13: 43797 | Y13: REGULER | AA13: ISLAM | AB13: WARGA NEGARA INDONESIA | AC13: JL RAYA KASIN AMPELDENTO | AD13: 19 | AE13: 07 | AF13: AMPELDENTO | AG13: KARANGPLOSO | AH13: LUAR MALANG | AI13: 65152 | AJ13: MALANG | AM13: Tidak ada | AN13: 082139720121 | AO13: 1 | AP13: Tidak ada | AS13: 16kg | AT13: 110cm | AV13: TIDAK | AW13: Tidak ada | AX13: BAHASA INDONESIA | AY13: Muhammad muflih | AZ13: 3507232608950001 | BA13: MALANG | BB13: 34937 | BC13: ISLAM | BD13: 081236950253 | BE13: SMA/SMK SEDERAJAT | BF13: PEDAGANG | BG13: TOKO BUAH MAHER | BH13: KASIN AMPELDENTO KARANGPLOSO RT 19 RW 07 MALANG | BI13: Tidak ada | BJ13: 10 juta per bulan | BK13: muflihm39@yahoo.com | BL13: Nabilah safinas | BM13: 3579036106970001 | BN13: MALANG | BO13: 35602 | BP13: ISLAM | BQ13: 082139720121 | BR13: SMA/SMK SEDERAJAT | BS13: IBU RUMAH TANGGA | BT13: TIDAK ADA | BU13: TIDAK ADA | BV13: Tidak ada | BW13: Tidak ada | BX13: Nabilahsafinas21@gmail.com
A14: 60 | I14: TAMAN KANAK-KANAK (TK) | J14: TK AL HUDA BAGUS | K14: JL. RONGGOWARSITO NO. 27 KLOJEN KOTA MALANG | M14: 2282 | N14: 3197150648 | O14: 3507221511200001 | P14: 3507221111190001 | Q14: MUHAMMAD ADHYAKSA ATQA ALFATIH | R14: 1A | S14: BERLIAN | T14: ATQA | U14: LAKI-LAKI | V14: MALANG | W14: 43780 | Y14: REGULER | AA14: ISLAM | AB14: WARGA NEGARA INDONESIA | AC14: JL. RAYA SENGKALING NO. 180 | AD14: 004 | AE14: 007 | AF14: MULYOAGUNG | AG14: DAU | AH14: LUAR MALANG | AI14: 65151 | AJ14: KAB. MALANG | AM14: 08974721122 | AN14: 08974721122 | AO14: 1 | AP14: 1 | AS14: 21 | AT14: 114 | AV14: TIDAK | AW14: BATUK, PILEK | AX14: INDONESIA | AY14: RIZKI DHIA PUTRA, Amd. | AZ14: 3515180911920007 | BA14: BENGKULU | BB14: 33917 | BC14: ISLAM | BD14: 081224774659 | BE14: S1 | BF14: WIRASWASTA | BG14: PT. PRISMA GLOBAL | BH14: DELTA TAMA V NO. 30 WARU SIDOARJO | BI14: 082131324881 | BJ14: 5.000.000 | BK14: rizkidhiaputra@gmail.com | BL14: ZULHULAIFAH PUTRI RAHMAWATI, S.H. | BM14: 3507224311940004 | BN14: MALANG | BO14: 34641 | BP14: ISLAM | BQ14: 08212344772 | BR14: S1 | BS14: ASN PPPK | BT14: DINAS LINGKUNGAN HIDUP KOTA MALANG | BU14: JL. BINGKIL NO. 1 KEL. CIPTOMULYO KEC. SUKUN KOTA MALANG | BV14: 0341 369377 | BW14: 3.200.000 | BX14: zulhulaifahputrir@gmail.com
A15: 97 | I15: TAMAN KANAK-KANAK (TK) | J15: TK ANAK SALEH MALANG | K15: JL. CANDI PANGGUNG INDAH NO. 1-3 MALANG | M15: 2286 | N15: 3205930359 | O15: 3501042909160012 | P15: 3501042802200002 | Q15: MUHAMMAD ARFAN FARDHAN KARIM | R15: 1A | S15: BERLIAN | T15: ARFAN | U15: LAKI-LAKI | V15: MALANG | W15: 43889 | Y15: Reguler | Z15: - | AA15: ISLAM | AB15: WARGA NEGARA INDONESIA | AC15: JL. LESTI II/12 MALANG 65123 | AD15: 006 | AE15: 006 | AF15: BUNULREJO | AG15: BLIMBING | AH15: BLIMBING | AI15: 65123 | AJ15: MALANG | AM15: - | AN15: +62 838-4893-0518 | AO15: 3 | AP15: 3 | AS15: 20.4 | AT15: 118 | AV15: TIDAK | AW15: - | AX15: JAWA / INDONEISA | AY15: Syahroni Hamsyah | AZ15: 3573012702840004 | BA15: MALANG | BB15: 30739 | BC15: ISLAM | BD15: 085755050010 | BE15: S1 | BF15: ASN DJKI | BG15: DJKI | BH15: JL. H. R. RASUNA SAID NO.KAV 8 9, RT.16/RW.4, KUNINGAN, EAST KUNINGAN, JAKARTA, SOUTH JAKARTA CITY, JAKARTA 12940 | BI15: - | BJ15: 5.000.0000 | BK15: hamsink27@gmail.com | BL15: Evi DWi Jayanti | BM15: 3501045105860009 | BN15: PACITAN | BO15: 31543 | BP15: ISLAM | BQ15: +62 838-4893-0518 | BR15: S1 | BS15: GURU TK ANAK SALEH MALANG | BT15: TK ANAK SALEH MALANG | BU15: PAUD TERPADU ANAK SALEH : JL. CANDI PANGGUNG INDAH 1-3 MALANG | BV15: 082229350007 | BW15: 1.800.000 | BX15: -
A16: 27 | I16: TAMAN KANAK-KANAK (TK) | J16: TK ANAK SALEH | K16: JLN. CANDI PANGGUNG INDAH 1-3 | M16: 2289 | N16: 3205298409 | O16: '3579031810180002 | P16: 3579031002200003 | Q16: MUHAMMAD BOBYARYA WIJAYA | R16: 1A | S16: BERLIAN | T16: BOBY | U16: LAKI-LAKI | V16: MALANG | W16: 43871 | Y16: REGULER | Z16: - | AA16: ISLAM | AB16: WARGA NEGARA INDONESIA | AC16: JLN. DRS. MOH HATTA , NO. 222 , PENDEM, JUNREJO. BATU | AD16: 05 | AE16: 01 | AF16: PENDEM | AG16: JUNREJO | AH16: LUAR MALANG | AI16: 65324 | AJ16: BATU | AM16: - | AN16: 085334106150 | AO16: 2 | AP16: 2 | AS16: 20 | AT16: 110 | AV16: TIDAK | AW16: DEMAM, BATUK, PILEK | AX16: INDONESIA | AY16: Sumarto | AZ16: 3503061303850003 | BA16: TRENGGALEK | BB16: 31119 | BC16: ISLAM | BD16: 85232620640 | BE16: SMA/SMK SEDERAJAT | BF16: KARYAWAN SWASTA | BG16: - | BH16: - | BI16: - | BJ16: 5.000.000 | BK16: naiilavirania @gmail.com | BL16: Dwi Ernawati | BM16: 3503064102910001 | BN16: TRENGGALEK | BO16: 33270 | BP16: ISLAM | BQ16: 085334106150 | BR16: SMA/SMK SEDERAJAT | BS16: IBU RUMAH TANGGA | BT16: - | BU16: - | BV16: - | BW16: - | BX16: naiilavirania@gmail.com | BY16: - | BZ16: -
A17: 76 | I17: TAMAN KANAK-KANAK (TK) | J17: KELOMPOK BERMAIN CHILDREN CENTRE BRAWIJAYA SMART SCHOOL | K17: JL. VETERAN NO.17, KETAWANGGEDE, KEC. LOWOKWARU, KOTA MALANG, JAWA TIMUR 65145 | M17: 2295 | N17: 3202582657 | O17: 3507221006150002 | P17: 3507222904200004 | Q17: MUHAMMAD ZUBAIR EZRA LAZUARDY | R17: 1A | S17: BERLIAN | T17: EZRA | U17: LAKI-LAKI | V17: MALANG | W17: 43950 | Y17: REGULER | Z17: - | AA17: ISLAM | AB17: WARGA NEGARA INDONESIA | AC17: JL. MULYOREJO NO. 36 | AD17: 001 | AE17: 002 | AF17: MULYOAGUNG | AG17: DAU | AH17: LUAR MALANG | AI17: 65151 | AJ17: MALANG | AM17: 082334050999 | AN17: 085231184999 | AO17: 2 | AP17: 1 | AS17: 16 | AT17: 106 | AV17: TIDAK | AW17: tidak ada | AX17: BAHASA INDONESIA | AY17: Mochammad Hannats Hanafi Ichsan, S.ST., M.T. | AZ17: 3507222912880001 | BA17: MALANG | BB17: 32506 | BC17: ISLAM | BD17: 082334050999 | BE17: S2 | BF17: DOSEN PNS | BG17: DEPARTEMEN INFORMATIKA, FAKULTAS ILMU KOMPUTER, UNIVERSITAS BRAWIJAYA | BH17: JL. VETERAN, KETAWANGGEDE, LOWOKWARU, KOTA MALANG, JAWA TIMUR, INDONESIA – 65145 | BI17: (0341) 577-911 | BJ17: 5000000 | BK17: hanas.hanafi@ub.ac.id | BL17: Aisshah Roesiana Dewi, S.ST., M.T. | BM17: 3573034312870002 | BN17: MALANG | BO17: 32114 | BP17: ISLAM | BQ17: 085231184999 | BR17: S2 | BS17: PENELITI | BT17: DEPARTEMEN TEKNIK INDUSTRI, FAKULTAS TEKNIK, UNIVERSITAS BRAWIJAYA | BU17: DEPARTEMEN TEKNIK INDUSTRI, FAKULTAS TEKNIK, UNIVERSITAS BRAWIJAYA JLN. MT. HARYONO 167, MALANG 65145, INDONESIA | BV17: +62 341 587710 | BW17: 3000000 | BX17: aisshah.roesiana@gmail.com | BY17: Prof. Dr. Siti Zubaidah, S.Pd, M.Pd | BZ17: MALANG | CA17: 24991 | CC17: 081334435234 | CD17: PROFESOR | CE17: Dosen
A18: 53 | I18: TAMAN KANAK-KANAK (TK) | J18: KARTIKA PRADANA | K18: JALAN AKORDION BARAT 2 TUNGGULWULUNG MALANG | M18: 2296 | N18: 320299422 | O18: 3573051209180004 | P18: 3573056203200002 | Q18: MYURA MAZIDAH ALZAR | R18: 1A | S18: BERLIAN | T18: MYURA | U18: PEREMPUAN | V18: MALANG | W18: 43912 | Y18: REGULER | AA18: ISLAM | AB18: WARGA NEGARA INDONESIA | AC18: PERMATA LAND B17 | AD18: 18 | AE18: 01 | AF18: TUNGGULWULUNG | AG18: LOWOKWARU | AH18: LOWOKWARU | AI18: 65143 | AJ18: MALANG | AM18: TIDAK ADA | AN18: 085641742667 | AO18: 2 | AP18: 1 | AS18: 16 | AT18: 110 | AV18: TIDAK | AW18: DEMAM, BATUK, PILEK | AX18: BAHASA INDONESIA DAN JAWA | AY18: AHMAD FIRDAUS NIZARUDIN, S.Hut. | AZ18: 3573051610890007 | BA18: MALANG | BB18: 32797 | BC18: ISLAM | BD18: 082245459771 | BE18: S1 | BF18: KARYAWAN SWASTA | BG18: BANK WOORI SAUDARA | BH18: JL. KAWI NO. 22, KEL.BANUMULYO KEC. KEPANJEN, KABUPATEN MALANG, JAWA TIMUR | BI18: TIDAK ADA | BJ18: 4.000.000 | BK18: nizarudin29@gmail.com | BL18: LUSVITA ANGGRAINI | BM18: 3572014203870004 | BN18: BLITAR | BO18: 31838 | BP18: ISLAM | BQ18: 085641742667 | BR18: S1 | BS18: KARYAWAN | BT18: UNIVERSITAS BRAWIJAYA | BU18: JALAN VETERAN | BV18: TIDAK ADA | BW18: 4.000.000 | BX18: lusvita.a@gmail.com | BY18: TIDAK ADA | BZ18: TIDAK ADA
A19: 82 | I19: TAMAN KANAK-KANAK (TK) | J19: TK NEGERI PEMBINA 1 MALANG | K19: JL. CIBOGO | M19: 2298 | N19: 31945563125 | O19: 3515050709180004 | P19: 3515051907190002 | Q19: NIRANKARA BIMASENA INDARSYAH | R19: 1A | S19: BERLIAN | T19: BIMA | U19: LAKI-LAKI | V19: MALANG | W19: 43665 | Y19: REGULER | AA19: ISLAM | AB19: WARGA NEGARA INDONESIA | AC19: GARDEN RESIDENCE BLOK SAKURA 1, MALANG | AD19: 43 | AE19: . | AF19: NGIJO | AG19: KARANGPLOSO | AH19: LUAR MALANG | AI19: 65152 | AJ19: MALANG | AM19: . | AN19: 082189672626 | AO19: 2 | AP19: 3 | AS19: 19.5 | AT19: 114 | AV19: TIDAK | AW19: tidak ada | AX19: INDONESIA, JAWA | AY19: DEDY INDARSYAH, SP. | AZ19: 3510102603310002 | BA19: BANYUWANGI | BB19: 33507 | BC19: ISLAM | BD19: 081249688025 | BE19: S1 | BF19: PEGAWAI BUMN | BG19: PTPN I REGIONAL 5 | BH19: KEBUN KALISAT JAMPIT BONDOWOSO | BJ19: 5.000.000 | BK19: dedyindarsyah@gmail.com | BL19: Dr. Wiwit Widyawati, SP. MP. | BM19: 3515056307900001 | BN19: SIDOARJO | BO19: 33077 | BP19: ISLAM | BQ19: 082189672626 | BR19: S3 | BS19: TENAGA PENDIDIK | BT19: FAKULTAS PERTANIAN UNIVERSITAS BRAWIJAYA | BU19: JL. VETERAN MALANG | BW19: 3.600.000 | BX19: wiwit23@ub.ac.id
A20: 61 | I20: TAMAN KANAK-KANAK (TK) | J20: OMAH BOCAH ANAFI | K20: SOEKARNO HATTA | M20: 2299 | N20: 3197088375 | O20: 3578080909140010 | P20: 3578082706190002 | Q20: NIZAM ABDUL HAFIDZ | R20: 1A | S20: BERLIAN | T20: NIZAM | U20: LAKI-LAKI | V20: SURABAYA | W20: 43643 | Y20: REGULER | AA20: ISLAM | AB20: WARGA NEGARA INDONESIA | AC20: MANALI HILL CLUSTER 2 BLOK B12 | AD20: 10 | AE20: 03 | AF20: TEGALGONDO | AG20: KARANGPLOSO | AH20: LUAR MALANG | AI20: 65152 | AJ20: MALANG | AM20: 085233208171 | AN20: 085233208171 | AO20: 1 | AP20: 1 | AS20: 30 | AT20: 120 | AV20: TIDAK | AW20: BATUK, PILEK | AX20: INDONESIA | AY20: Ardy Noviawan Putra, A.Md., S.Sos | AZ20: 3578210311890001 | BA20: SURABAYA | BB20: 32815 | BC20: ISLAM | BD20: 085233208171 | BE20: S1 | BF20: WIRAUSAHA | BG20: CV PARAS PESONA ABADI | BH20: JL KAPAS KRAMPUNG NO 214A, SURABAYA | BJ20: 10000000 | BK20: ardynoviawan@gmail.com | BL20: Novi Aditya Rosalita, S.M., M.SM | BM20: 3578086711890005 | BN20: SURABAYA | BO20: 32839 | BP20: ISLAM | BQ20: 085733300019 | BR20: S2 | BS20: WIRAUSAHA | BT20: CV PARAS PESONA ABADI | BU20: JL KAPAS KRAMPUNG NO 214A, SURABAYA | BW20: 10000000 | BX20: noviadityarosalita@gmail.com
A21: 5 | I21: TAMAN KANAK-KANAK (TK) | J21: ANAK SALEH | K21: JL. CANDI PANGGUNG INDAH NO. 1-3, MOJOLANGU, KEC. LOWOKWARU, KOTA MALANG, JAWA TIMUR. | M21: 2302 | N21: 3202869285 | O21: 3573051902130012 | P21: 3573050704200002 | Q21: RAMANDARA DIMAS HERMANTO | R21: 1A | S21: BERLIAN | T21: RAMA | U21: LAKI-LAKI | V21: MALANG | W21: 43928 | Y21: REGULER | AA21: ISLAM | AB21: WARGA NEGARA INDONESIA | AC21: JL CANDIMENDUT 4 KAV1 NO 1 PERM BAMBOE PARK | AD21: 002 | AE21: 008 | AF21: TULUSREJO | AG21: LOWOKWARU | AH21: LOWOKWARU | AI21: 65141 | AJ21: KOTA MALANG | AM21: 0341497939 | AN21: 081333118693 | AO21: 3 | AP21: 2 | AS21: 18 | AT21: 110 | AV21: TIDAK | AW21: Bidur | AX21: JAWA DAN INDONESIA | AY21: Dony Hermanto, SAB | AZ21: 3573052207790006 | BA21: MADIUN | BB21: 29058 | BC21: ISLAM | BD21: 082245576698 | BE21: S1 | BF21: WIRASWASTA | BG21: SWASTA | BH21: JL CANDI MENDUT 4 KAV 1 NO 1 PERM, BAMBOE PARK | BI21: 0341 497939 | BJ21: 6000000 | BK21: dyhermanto@gmail.com | BL21: Mamik Suhariyani, SAP | BM21: 3573056308810001 | BN21: MALANG | BO21: 30186 | BP21: ISLAM | BQ21: 081333118693 | BR21: S1 | BS21: IBU RUMAH TANGGA | BT21: RUMAH | BU21: JL. CANDIMENDUT 4 PERM. BAMBOEPARK KAV.1 NO 1 | BV21: 0341497939 | BW21: 0 | BX21: mshermanto@gmail.com
A22: 2 | I22: TAMAN KANAK-KANAK (TK) | J22: TK PERMATA IMAN 1 | K22: JL. BATU PERMATA NO. 9 TLOGOMAS | M22: 2303 | N22: 3195719568 | O22: 3510161710130001 | P22: 3510164503190004 | Q22: RAYNA MECCA FERHANADYA | R22: 1A | S22: BERLIAN | T22: MEME | U22: PEREMPUAN | V22: MALANG | W22: 43529 | Y22: REGULER | AA22: ISLAM | AB22: WARGA NEGARA INDONESIA | AC22: PERUM PERMATA HIJAU. BLOK B NO 24 | AD22: 3 | AE22: 9 | AF22: TLOGOMAS | AG22: LOWOKWARU | AH22: LOWOKWARU | AI22: 65144 | AJ22: MALANG | AM22: 082221122452 | AN22: 082221122452 | AO22: 3 | AP22: 2 | AS22: 21,6 kg | AT22: 116,5 cm | AV22: TIDAK | AW22: BATUK | AX22: INDONESIA | AY22: Fery Eriyanto, SH | AZ22: 5271012001830006 | BA22: BANYUWANGI | BB22: 30336 | BC22: ISLAM | BD22: 082220222666 | BE22: S1 | BF22: PNS | BG22: KPP PRATAMA TOLI TOLI | BH22: JL. MOGAMU NO.102 TUWELEY, KEC. BAOLAN, KAB. TOLI TOLI, SULAWESI TENGAH 94514 | BI22: ( 0453 ) 23765 | BJ22: Rp. 25,000,000 | BK22: ferye886@gmail.com | BL22: dr. Hanum Lukitaningrum | BM22: 5271016409850003 | BN22: MALANG | BO22: 31314 | BP22: ISLAM | BQ22: 082221122452 | BR22: S1 | BS22: IBU RUMAH TANGGA | BT22: RUMAH | BU22: PERUM. PERMATA HIJAU BLOK B NO. 24 | BV22: 082221122452 | BW22: - | BX22: lukitaningrum@gmail.con | BY22: dr. Hanum Lukitaningrum | BZ22: MALANG | CA22: 31314 | CC22: 082221122452 | CD22: S1 | CE22: Ibu Rumah Tangga
A23: 63 | I23: TAMAN KANAK-KANAK (TK) | J23: PAUD TERPADU ANAK SALEH | K23: JL CANDI PANGGUNG INDAH NO 1-3 | M23: 2308 | N23: 3198466212 | O23: 3573021909190007 | P23: 3573026907190003 | Q23: RT ELEANOR AMARA PRATISHTA | R23: 1A | S23: BERLIAN | T23: LEA | U23: PEREMPUAN | V23: MALANG | W23: 43675 | Y23: PDBK (BERKEBUTUHAN KHUSUS) | Z23: ASD ringan | AA23: ISLAM | AB23: WARGA NEGARA INDONESIA | AC23: PERMATA JINGGA WEST AREA H / 15 | AD23: 10 | AE23: 06 | AF23: TUNGGULWULUNG | AG23: LOWOKWARU | AH23: LOWOKWARU | AI23: 65143 | AJ23: KOTA MALANG | AM23: - | AN23: 081333191599 | AO23: 1 | AP23: - | AS23: 13 kg | AT23: 108 cm | AV23: TIDAK | AW23: - | AX23: BAHASA INDONESIA | AY23: ADITYA MAHATAMTAMA ARYA MAHESA, S.Ikom | AZ23: 3573042608900004 | BA23: MALANG | BB23: 33111 | BC23: ISLAM | BD23: 081333191599 | BE23: S1 | BF23: WIRASWASTA | BG23: PT LOGAM ASIR | BH23: JL RAYA BLITAR NO 106-106, NGUNUT, TULUNGAGUNG | BI23: - | BJ23: Rp 30.000.000 - 40.000.000 / bulan | BK23: firanurbillah92@gmail.com | BL23: FIRA NURBILLAH, S.I.KOM | BM23: 3573054210920001 | BN23: MALANG | BO23: 33879 | BP23: ISLAM | BQ23: 081333191599 | BR23: S1 | BS23: IRT | BT23: RUMAH | BU23: - | BV23: - | BW23: - | BX23: firanurbillah92@gmail.com | BY23: SRI WIJAYAWATI | BZ23: MALANG | CC23: 08123305003 | CD23: S1 | CE23: WIRASWASTA
A24: 46 | I24: TAMAN KANAK-KANAK (TK) | J24: TK ANDALUSIA KIDS | K24: MERJOSARI MALANG | M24: 2309 | O24: 3516121211180006 | P24: 3516122705190002 | Q24: SALMAN MALIK AKHMAD | R24: 1A | S24: BERLIAN | T24: ISHAL | U24: LAKI-LAKI | V24: MALANG | W24: 43612 | Y24: REGULER | AA24: ISLAM | AB24: WARGA NEGARA INDONESIA | AC24: PERUM PERMATA JINGGA BLOK PINUS NO 36 | AD24: 07 | AE24: 06 | AF24: TUNGGULWULUNG | AG24: LOWOKWARU | AH24: LOWOKWARU | AI24: 65143 | AJ24: MALANG | AM24: 081333555026 | AN24: 081334480834 | AO24: 1 | AP24: 1 | AS24: 20 | AT24: 117 | AV24: TIDAK | AW24: - | AX24: BAHASA INDONESIA | AY24: Akhmad Amirudin, S.AP, M.AP, M.Pol.sc, P.hD. | AZ24: 3516122604870001 | BA24: MOJOKERTO | BB24: 31893 | BC24: ISLAM | BD24: 081333555026 | BE24: S3 | BF24: DOSEN DAN PENGUSAHA | BG24: UNIVERSITAS BRAWIJAYA | BH24: JL. MT. HARYONO NO.163, KETAWANGGEDE, KEC. LOWOKWARU, KOTA MALANG | BI24: 0341-553737 | BJ24: +- 50juta | BK24: akhmadamirudin@gmail.com | BL24: Kirana Nur Novia Dewi, S.AP. | BM24: 3301215111970003 | BN24: CILACAP | BO24: 35745 | BP24: ISLAM | BQ24: 081334480834 | BR24: S1 | BS24: IRT DAN PENGUSAHA | BT24: - | BU24: - | BV24: - | BW24: -+ 20juta | BX24: kiranad198@gmail.com
A25: 58 | I25: TAMAN KANAK-KANAK (TK) | J25: TK OMAH BOCAH ANNAAFII | K25: PERUM GRIYASANTA L301, MOJOLANGU, KEC. LOWOKWARU, KOTA MALANG, JAWA TIMUR 65141 | M25: 2310 | N25: 3199563005 | O25: 3308180706170004 | P25: 3308185309190004 | Q25: SEANNA RADINKA DIKSA | R25: 1A | S25: BERLIAN | T25: SEA | U25: PEREMPUAN | V25: MAGELANG | W25: 43721 | Y25: REGULER | AA25: ISLAM | AB25: WARGA NEGARA INDONESIA | AC25: EAST GARDEN RESIDENCE BLOK SALVIA 12 | AD25: 0 | AE25: 0 | AF25: NGIJO | AG25: KARANGPLOSO | AH25: LUAR MALANG | AI25: 65152 | AJ25: KABUPATEN MALANG | AM25: - | AN25: 085643871891 | AO25: 1 | AP25: 1 | AS25: 16 | AT25: 113.5 | AV25: TIDAK | AW25: BATUK, PILEK | AX25: INDONESIA | AY25: RONDISE SYIFA DIKSA | AZ25: 3308180703890006 | BA25: SURABAYA | BB25: 32574 | BC25: ISLAM | BD25: 085741805789 | BE25: S1 | BF25: PEGAWAI SWASTA | BG25: PT ASTRA GRAPHIA TBK | BH25: JL. BOROBUDUR AGUNG BARAT VII NO.8B, MOJOLANGU, LOWOKWARU, MALANG | BJ25: 10 juta | BK25: badamers.02@gmail.com | BL25: SOFIA AGUSTINA | BM25: 3308205708890002 | BN25: MAGELANG | BO25: 32737 | BP25: ISLAM | BQ25: 085643871891 | BR25: S1 | BS25: ASN | BT25: KPP PRATAMA MALANG UTARA | BU25: JL. JAKSA AGUNG SUPRAPTO KAV.29-31 KLOJEN, KOTA MALANG | BW25: 10 JUTA | BX25: SOFIAGUSTINA.SA@GMAIL.COM
A26: 70 | I26: BUSTHANUL ATHFAL (BA) | J26: BA RESTU 1 MALANG | K26: JL. BANDUNG | M26: 2320 | N26: 3198531177 | O26: 3573011105150006 | P26: 3573014305190004 | Q26: ZASKIA MAKHAYLA RABBINA | R26: 1A | S26: BERLIAN | T26: KHAYLA | U26: PEREMPUAN | V26: MALANG | W26: 43588 | Y26: REGULER | AA26: ISLAM | AB26: WARGA NEGARA INDONESIA | AC26: JL. ZAENAL ZAKSE GG 2 NO.2511 | AD26: 06 | AE26: 04 | AF26: JODIPAN | AG26: BLIMBING | AH26: BLIMBING | AI26: 65127 | AJ26: KOTA MALANG | AM26: 087856888584 | AN26: 087856888584 | AO26: 2 | AP26: 1 | AS26: 17,5 | AT26: 110cm | AV26: TIDAK | AW26: BATUK | AX26: BAHASA INDONESIA | AY26: Imam Turmudzi | AZ26: 3573030706880002 | BA26: MALANG | BB26: 32301 | BC26: ISLAM | BD26: 081232567488 | BE26: SMP/MTs SEDERAJAT | BF26: DIREKTUR PT. PERSIBA BERIMAN | BG26: PERSIBA BERIMAN | BH26: JL. GATOT SUBROTO NO.72 PANCORAN JAKARTA SELATAN | BI26: 0 | BJ26: 10jt | BK26: imamvws@gmail.com | BL26: Vina Wulan Sari | BM26: 3573015011890001 | BN26: MALANG | BO26: 32822 | BP26: ISLAM | BQ26: 087856888584 | BR26: S1 | BS26: IBU RUMAH TANGGA | BT26: 0 | BU26: 0 | BV26: 0 | BW26: 0 | BX26: vilansa99@gmail.com
A27: 94 | I27: RAUDHATUL ATHFAL (RA) | J27: RA MIFTAHUL HUDA | K27: JL MASJID NO 23 KEC KARANGPLOSO KAB MALANG | M27: 2321 | N27: 3198980505 | O27: 3271042503170001 | P27: 3271045811190003 | Q27: ZAURA CALIANNA JASMINE | R27: 1A | S27: BERLIAN | T27: ZAURA | U27: PEREMPUAN | V27: MALANG | W27: 43787 | Y27: REGULER | AA27: ISLAM | AB27: WARGA NEGARA INDONESIA | AC27: JL COKROAMINOTO LOWOKSARI NO 354 RT/RW 05/05 NGENEP, KARANGPLOSO KAB. MALANG | AD27: 5 | AE27: 5 | AF27: NGENEP | AG27: KARANGPLOSO | AH27: LUAR MALANG | AI27: 65152 | AJ27: MALANG | AM27: 085723086974 | AN27: 089738331974 | AO27: 2 | AP27: Abqori Kenzie Ramadhan | AS27: 18.7 | AT27: 106 | AV27: ADA | AW27: BATUK | AX27: INDONESIA | AY27: Hasannudin, S. T. P | AZ27: 3271041511890004 | BA27: BOGOR | BB27: 32827 | BC27: ISLAM | BD27: 085723086974 | BE27: S1 | BF27: PNS | BG27: BRMPTAS MALANG | BH27: JL RAYA KARANGPLOSO KM 4 MALANG | BI27: 0341491447 | BJ27: 7000000 | BK27: hasan_abuy@yahoo.co.id | BL27: Fajar Lestary | BM27: 3271064601910001 | BN27: BOGOR | BO27: 33244 | BP27: ISLAM | BQ27: 089638331974 | BR27: S1 | BS27: PNS | BT27: LABORATORIUM BEA CUKAI NGURAH RAI | BU27: JL AIRPORT NGURAH RAI TUBAN BADUNG BALI | BV27: 089638331974 | BW27: 14000000 | BX27: fajarlesta@yahoo.co.id | BY27: Imas Sumarni, S. Pd | BZ27: BOGOR | CA27: 24881 | CC27: 087780117105 | CD27: S1 | CE27: PNS
A28: 7 | I28: TAMAN KANAK-KANAK (TK) | J28: TK ANAK SALEH | K28: JL. CANDI PANGGUNG INDAH NO. 1-3, DESA MOJOLANGU, KECAMATAN LOWOKWARU, KOTA MALANG | M28: 2322 | N28: 3197486497 | O28: 3514080404180002 | P28: 3514086906190001 | Q28: ZEEANA ASEEQA PUTRI WIJAYA | R28: 1A | S28: BERLIAN | T28: ZEE | U28: PEREMPUAN | V28: MALANG | W28: 43645 | Y28: REGULER | AA28: ISLAM | AB28: WARGA NEGARA INDONESIA | AC28: MUTIARA JINGGA RESIDENCE A7 | AD28: 7 | AE28: 4 | AF28: TASIKMADU | AG28: LOWOKWARU | AH28: LOWOKWARU | AI28: 65143 | AJ28: KOTA MALANG | AM28: - | AN28: 082244440442 | AO28: Pertama | AP28: Satu | AS28: 16 kg | AT28: 108 cm | AV28: TIDAK | AW28: DEMAM, BATUK, PILEK | AX28: INDONESIA | AY28: Nofian Wijaya, S.Pd.,M.H. | AZ28: 3514081811920001 | BA28: PASURUAN | BB28: 33926 | BC28: ISLAM | BD28: 082244440443 | BE28: S2 | BF28: GURU | BG28: SMP NEGERI 1 PURWOSARI | BH28: JL. RAYA PUNTIR NO.128, DONOREJO, MARTOPURO, KEC. PURWOSARI, PASURUAN, JAWA TIMUR 67162 | BJ28: 3.500.000 | BK28: nofianwijaya25@gmail.com | BL28: Mifta Kharima Akbari Putri, M.Pd. | BM28: 3507244201920003 | BN28: MALANG | BO28: 33605 | BP28: ISLAM | BQ28: 082244440442 | BR28: S2 | BS28: GURU | BT28: SMP NEGERI 04 BATU | BU28: JL. PANGERAN DIPONEGORO NO.18, TULUNGREJO, KEC. BUMIAJI, KOTA BATU, JAWA TIMUR 65336 | BW28: 3.000.000 | BX28: kharimamifta@gmail.com | BY28: Titin Suhernaning, S.Pd. | BZ28: MALANG | CA28: 22881 | CC28: +62 822-5701-5101 | CD28: S1
A29: 83 | I29: TAMAN KANAK-KANAK (TK) | J29: TK LAB MALANG | K29: JL. MAGELANG NO. 2, SUMBERSARI, KEC. LOWOKWARU, KOTA MALANG, JAWA TIMUR | M29: 2243 | N29: 3186347593 | O29: 3507241102190013 | P29: 3507222412180001 | Q29: ARJUNA SAKHA PURBAYA | R29: 1B | S29: MUTIARA | T29: JUNA | U29: LAKI-LAKI | V29: MALANG | W29: 43458 | Y29: PDBK (BERKEBUTUHAN KHUSUS) | Z29: Cerebral Palsy | AA29: ISLAM | AB29: WARGA NEGARA INDONESIA | AC29: PUNCAK DIENG JJ1 NO7 | AD29: 003 | AE29: 007 | AF29: KALISONGO | AG29: DAU | AH29: LUAR MALANG | AI29: 65151 | AJ29: MALANG | AM29: - | AN29: 082230111110 | AO29: 1 | AP29: I | AS29: 20 | AT29: 110 | AV29: TIDAK | AW29: BATUK, PILEK | AX29: BAHASA INDONESIA | AY29: A Hendik Purbaya Mahadi Putra, SE., MM. | AZ29: 3507221109910003 | BA29: SURABAYA | BB29: 33492 | BC29: ISLAM | BD29: 081333221110 | BE29: S2 | BF29: SWASTA | BG29: STAFF ALHI DPR RI | BH29: JL. GATOT SUBROTO NO.1, RT.1/RW.3, SENAYAN, KECAMATAN TANAH ABANG, KOTA JAKARTA PUSAT, DAERAH KHUSUS IBUKOTA JAKARTA 10270 | BJ29: Rp 10.000.000 | BK29: hendikpurbaya@gmail.com | BL29: Micky Dita Avrilia, SE., MM. | BM29: 3507047004920002 | BN29: MALANG | BO29: 33724 | BP29: ISLAM | BQ29: 082230111110 | BR29: S2 | BS29: WIRASWASTA | BT29: SATU ATTIRE | BU29: JL CAKALANG 180, KOTA MALANG | BW29: 5.000.000 | BX29: mickydit@gmail.com
A30: 85 | I30: TAMAN KANAK-KANAK (TK) | J30: KARTIKA PRADANA | K30: JL. SIMPANG AKORDEON NO.2, TUNGGULWULUNG, KEC. LOWOKWARU, KOTA MALANG, JAWA TIMUR 65147 | M30: 2227 | N30: 3187956648 | O30: 3573051902180005 | P30: 3573055912180002 | Q30: AISYAH ZAHEERA THARYA | R30: 1B | S30: MUTIARA | T30: ZAHEERA | U30: PEREMPUAN | V30: MALANG | W30: 43453 | Y30: REGULER | AA30: ISLAM | AB30: WARGA NEGARA INDONESIA | AC30: PERUMAHAN GRAND ARUMBA BLOK I NO 16 | AD30: 1 | AE30: 4 | AF30: TUNGGULWULUNG | AG30: LOWOKWARU | AH30: LOWOKWARU | AI30: 65143 | AJ30: MALANG | AM30: 085321483355 | AN30: 085321483355 | AO30: 1 | AP30: 1 | AS30: 19 | AT30: 108 | AV30: ADA | AW30: TB | AX30: INDONESIA | AY30: M Nashiruddin Abubakar S.T | AZ30: 3573052601890001 | BA30: MALANG | BB30: 32534 | BC30: ISLAM | BD30: 085321483355 | BE30: S1 | BF30: KARYAWAN SWASTA | BG30: PT TUMBUH BERSAMA NANO | BH30: MAYAPADA TOWER 1, JL. JENDERAL SUDIRMAN NO.KAV. 28 20TH FLOOR, SUITE 03A, KARET KUNINGAN, KECAMATAN SETIABUDI, KOTA JAKARTA SELATAN, DAERAH KHUSUS IBUKOTA JAKARTA 12920 | BJ30: 15000000 | BK30: nashiruddin.abubakar@gmail.com | BL30: Irna FIbianti S.S, S.Pd | BM30: 3573024706890001 | BN30: MALANG | BO30: 32666 | BP30: ISLAM | BQ30: 087754451898 | BR30: S1 | BS30: GURU | BT30: TBI (THE BRITISH INSTITUTE) | BU30: JL. SOEKARNO HATTA NO.A.2, MOJOLANGU, KEC. LOWOKWARU, KOTA MALANG, JAWA TIMUR 65142 | BW30: 2000000-3000000 | BX30: irnafibianti@gmail.com
A31: 31 | I31: TAMAN KANAK-KANAK (TK) | J31: TK ANAK SALEH | K31: JL. CANDI PANGGUNG INDAH 1-3 MALANG | M31: 2229 | N31: 3205188675 | O31: 3573040112140007 | P31: 3573044601200001 | Q31: AKLEEMA HAJEERA FERRYANTO | R31: 1B | S31: MUTIARA | T31: AKIMA | U31: PEREMPUAN | V31: MALANG | W31: 43836 | Y31: REGULER | AA31: ISLAM | AB31: WARGA NEGARA INDONESIA | AC31: JL. RAYA CANDI II / 253 | AD31: 005 | AE31: 002 | AF31: KARANGBESUKI | AG31: SUKUN | AH31: SUKUN | AI31: 65146 | AJ31: KOTA MALANG | AM31: 081333833311 | AN31: 087859928461 | AO31: 2 | AP31: 1 | AS31: 16.4 kg | AT31: 105 cm | AV31: TIDAK | AW31: BATUK, PILEK | AX31: BAHASA INDONESIA | AY31: Ferry Andi Susanto A,Md | AZ31: 3573041002900005 | BA31: MALANG | BB31: 32914 | BC31: ISLAM | BD31: 081333833311 | BE31: SMA/SMK SEDERAJAT | BF31: PEDAGANG | BG31: UD. PUTERA DASRIM | BH31: JL. RAYA CANDI II NO.251 | BI31: 081333833311 | BJ31: 7 jt | BK31: ferryas10@gmail.com | BL31: Vita Valianta | BM31: 3205017001900002 | BN31: GARUT | BO31: 32903 | BP31: ISLAM | BQ31: 087859928461 | BR31: SMA/SMK SEDERAJAT | BS31: IBU RUMAH TANGGA | BT31: RUMAH | BU31: JL. RAYA CANDI II / 253 | BV31: 087859928461 | BW31: 0 | BX31: valiantavita@gmail.com
A32: 49 | I32: TAMAN KANAK-KANAK (TK) | J32: PAUD KAMILIA | K32: SAWOJAJAR | M32: 2237 | N32: 3193132028 | O32: 3573032407140008 | P32: 3573034812190002 | Q32: AMAYRA FATHIA ADMAZIA | R32: 1B | S32: MUTIARA | T32: AYRA | U32: PEREMPUAN | V32: MALANG | W32: 43807 | Y32: REGULER | AA32: ISLAM | AB32: WARGA NEGARA INDONESIA | AC32: JL SIMPANG DANAU LIMBOTO TIMUR 2 A5 H22 | AD32: 04 | AE32: 14 | AF32: SAWOJAJAR | AG32: KEDUNGKANDANG | AH32: KEDUNGKANDANG | AI32: 65139 | AJ32: KOTA MALANG | AM32: 081233234696 | AN32: 081233234696 | AO32: 2 | AP32: 1 | AS32: 15 | AT32: 108 | AV32: TIDAK | AW32: Tidak ada | AX32: BAHASA INDONESIA | AY32: Bima Aziz Muttaqi S.AP | AZ32: 3575011110860002 | BA32: PASURUAN | BB32: 31696 | BC32: ISLAM | BD32: 081233234696 | BE32: S1 | BF32: WIRAUSAHA | BG32: ZEA GROSIR | BH32: JL. SIMPANG DANAU LIMBOTO TIMUR 2 A5 H21 | BI32: 081233234696 | BJ32: 5000000 | BK32: bimamuttaqi@gmail.com | BL32: Rr Addini Zea Prameswari S.AB | BM32: 3573036506870002 | BN32: MALANG | BO32: 31953 | BP32: ISLAM | BQ32: 085646363936 | BR32: S1 | BS32: WIRAUSAHA | BT32: ZEA GROSIR | BU32: DANAU LIMBOTO TIMUR A5H22 | BV32: 085646363936 | BW32: 5000000 | BX32: dinizea05@gmail.com
A33: 13 | I33: TAMAN KANAK-KANAK (TK) | J33: PAUD TERPADU ANAK SALEH | K33: JLN CANDI PANGGUNG INDAH | M33: 2238 | N33: 3190327329 | O33: 3579032909160006 | P33: 3579034408190001 | Q33: AMIRA JASMINE ELMUBAREK | R33: 1B | S33: MUTIARA | T33: JASMINE | U33: PEREMPUAN | V33: MALANG | W33: 43681 | Y33: REGULER | AA33: ISLAM | AB33: WARGA NEGARA INDONESIA | AC33: LEMBAH DELIMA RESIDENCE NO 9 | AD33: 10 | AE33: 10 | AF33: TEMAS | AG33: BATU | AH33: LUAR MALANG | AI33: 65315 | AJ33: BATU | AM33: 0 | AN33: 08123369298 | AO33: 2 | AP33: 1 | AS33: 17kg | AT33: 110cm | AV33: TIDAK | AW33: BATUK | AX33: INDONESIA | AY33: Abdulloh Charis | AZ33: 3579030207890004 | BA33: MALANG | BB33: 32691 | BC33: ISLAM | BD33: 081230079978 | BE33: S1 | BF33: KARYAWAN SWASTA | BG33: PT DIRI ARTHA SEHAT | BH33: JLN. KEBON JERUK BARU JAKARTA BARAT | BI33: 0 | BJ33: 25.000.000 - 50.000.000 | BK33: me@chars.me | BL33: Ayu Miranti Puji Lestari | BM33: 3506177010920001 | BN33: KEDIRI | BO33: 33907 | BP33: ISLAM | BQ33: 081233690298 | BR33: S1 | BS33: WIRASWASTA | BT33: CAFEIN (COLD PRESSED ERA & JERUK LOKAL MALANG) | BU33: JLN BENDUNGAN SIGURA-GURA | BV33: 0 | BW33: >10.000.000 | BX33: ayumiranti@chars.me
A34: 22 | I34: TAMAN KANAK-KANAK (TK) | J34: TK LABORATORIUM UM | K34: JL. MAGELANG NO.2, RW.3, SUMBERSARI, KEC. LOWOKWARU, KOTA MALANG, JAWA TIMUR 65145 | M34: 2241 | N34: 3193961919 | O34: 3573052303200008 | P34: 3573055403200001 | Q34: ANGSANA KILAU MALINI | R34: 1B | S34: MUTIARA | T34: ANGSANA | U34: PEREMPUAN | V34: MALANG | W34: 43904 | Y34: REGULER | AA34: ISLAM | AB34: WARGA NEGARA INDONESIA | AC34: PERUM TUNJUNG SEKAR DAMAI Q-19, LOWOKWARU, MALANG | AD34: 010 | AE34: 004 | AF34: TUNJUNGSEKAR | AG34: LOWOKWARU | AH34: LOWOKWARU | AI34: 65142 | AJ34: MALANG | AM34: 081329628967 | AN34: 081329628967 | AO34: 1 | AP34: 1 | AS34: 18 | AT34: 110 | AV34: TIDAK | AW34: BATUK | AX34: BAHASA INDONESIA | AY34: Alan Sigit Fibrianto, S.Pd., M.Sos. | AZ34: 3312110402930002 | BA34: WONOGIRI | BB34: 34004 | BC34: ISLAM | BD34: 081329628967 | BE34: S2 | BF34: DOSEN | BG34: UNIVERSITAS NEGERI MALANG (UM) | BH34: JL. SEMARANG, NO. 05, KOTA MALANG | BI34: 0341-551312 | BJ34: 7.500.000 | BK34: alan.sigit.fis@um.ac.id | BL34: Ananda Dwitha Yuniar, S.I.Kom., M.A. | BM34: 3573056406930003 | BN34: MALANG | BO34: 34144 | BP34: ISLAM | BQ34: 081333015283 | BR34: S2 | BS34: DOSEN | BT34: UNIVERSITAS NEGERI MALANG (UM) | BU34: JL. SEMARANG, NO. 05, KOTA MALANG | BV34: 0341-551312 | BW34: 7.500.000 | BX34: ananda.dwitha.fis@um.ac.id
A35: 78 | I35: TAMAN KANAK-KANAK (TK) | J35: ANDALUSIA KIDS MERJOSARI | K35: JLN. JOYOGRAND, MERJOSARI MAKANG | M35: 2249 | O35: 3573050401210002 | P35: 3573056803200006 | Q35: AWFARA ZIYA ARZAQINA WIKA | R35: 1B | S35: MUTIARA | T35: ZIYA | U35: PEREMPUAN | V35: MALANG | W35: 43918 | Y35: REGULER | AA35: ISLAM | AB35: WARGA NEGARA INDONESIA | AC35: PERUMAHAN PERMATA JINGGA BLOK ANGGREK VI NO 29, LOWOKWARU, KOTA MALANG, JAWA TIMUR 65142 | AD35: 008 | AE35: 006 | AF35: TUNGGULWULUNG | AG35: LOWOKWARU | AH35: LOWOKWARU | AI35: 65142 | AJ35: MALANG | AM35: 082244433392 | AN35: 082244433392 | AO35: 1 | AP35: 1 | AS35: 19 | AT35: 120 | AV35: TIDAK | AW35: BATUK, PILEK | AX35: INDONESIA | AY35: Dr.dr. Alfian Wika Cahyono, M.Biomed | AZ35: 9202070401920001 | BA35: MANOKWARI (PAPUA BARAT) | BB35: 33607 | BC35: ISLAM | BD35: 082244433392 | BE35: S3 | BF35: DOKTER DAN WIRASWASTA | BG35: RS WARON HOSPITAL & WIKACELL | BH35: JLN SOEKARNO HATTA D505 MALANG | BJ35: 40.000.000,- | BK35: wikacahyo92@gmail.com | BL35: dr. Wiji Astuti | BM35: 3507234509910004 | BN35: MANOKWARI | BO35: 33486 | BP35: ISLAM | BQ35: 085344534559 | BR35: S1 | BS35: DOKTER | BT35: KLINIK AKURA MALANG | BU35: JLN. MAYJEN PANJAITAN | BW35: 3.000.0000 | BX35: Wijiazis18@gmail.com
A36: 12 | I36: TAMAN KANAK-KANAK (TK) | J36: TK ISLAMIC CENTRE SURABAYA | K36: JLN. RAYA DUKUH KUPANG NO. 122-124, SURABAYA | M36: 2253 | N36: 3191518965 | O36: 3175072406190071 | P36: 3175075806190004 | Q36: CLEMIRA YUMNA BASYAR | R36: 1B | S36: MUTIARA | T36: CLEMIRA/UNA | U36: PEREMPUAN | V36: BEKASI | W36: 43634 | Y36: REGULER | AA36: ISLAM | AB36: WARGA NEGARA INDONESIA | AC36: JL. KULINTANG NO. 7, PERUM. TUNGGUL KENCANA | AD36: 12 | AE36: 01 | AF36: TUNGGUL WULUNG | AG36: LOWOKWARU | AH36: LOWOKWARU | AI36: 65143 | AJ36: KOTA MALANG | AM36: 081287690480 | AN36: 0812876904780 | AO36: 1 | AP36: 0 | AS36: 16 | AT36: 110 | AV36: TIDAK | AW36: BATUK, PILEK | AX36: BAHASA INDONESIA | AY36: JOURAST SYAHRIANDY RIFKY | AZ36: 3175070103930005 | BA36: JAKARTA | BB36: 34029 | BC36: ISLAM | BD36: 082294109312 | BE36: S1 | BF36: KARYAWAN SWASTA | BG36: PT. MOTASA INDONESIA | BH36: CIPUTRA WORLD OFFICE TOWER, JL. MAYJEN SUNGKONO SURABAYA | BJ36: 15.000.000 | BK36: jourastjordy93@gmail.com | BL36: FIRIS BASMA LANJAR,STP. | BM36: 3275024105900022 | BN36: JAKARTA | BO36: 32994 | BP36: ISLAM | BQ36: 081287690480 | BR36: S1 | BS36: IBU RUMAH TANGGA | BT36: RUMAH | BU36: JL. KULINTANG KAV 7 | BW36: Dari Suami | BX36: fortuna.irish@gmail.com
A37: 75 | I37: TAMAN KANAK-KANAK (TK) | J37: TK ANAK SALEH | K37: JL.CANDI PANGGUNG INDAH 1 - 3 | M37: 2256 | N37: 31966991309 | O37: 3573052611180009 | P37: 3573050305190005 | Q37: DZAFLAN TRISHAKEEL PUTRA | R37: 1B | S37: MUTIARA | T37: DZAFLAN | U37: LAKI-LAKI | V37: MALANG | W37: 43588 | Y37: REGULER | AA37: ISLAM | AB37: WARGA NEGARA INDONESIA | AC37: JL.GAJAYANA 32 | AD37: 04 | AE37: 03 | AF37: KETAWANGGEDE | AG37: LOWOKWARU | AH37: LOWOKWARU | AI37: 65145 | AJ37: KOTA MALANG | AM37: - | AN37: 082140009929 | AO37: 3 | AP37: 3 | AS37: 17 | AT37: 115 | AV37: TIDAK | AW37: BATUK | AX37: BAHASA INDONESIA | AY37: Eka Putra Sultana | AZ37: 3578112010810003 | BA37: SURABAYA | BB37: 29879 | BC37: ISLAM | BD37: 082143845995 | BE37: SMA/SMK SEDERAJAT | BF37: WIRASWASTA | BG37: - | BH37: - | BJ37: Rp.3.000.000 - Rp.5.000.000 | BK37: psychopathwear5@gmail.com | BL37: Sherli Fatma Yuza | BM37: 1304014210920004 | BN37: BUKITTINGGI | BO37: 33879 | BP37: ISLAM | BQ37: 082140009929 | BR37: SMA/SMK SEDERAJAT | BS37: IBU RUMAH TANGGA | BT37: - | BU37: - | BW37: - | BX37: psychopathwear5@gmail.com
A38: 52 | I38: TAMAN KANAK-KANAK (TK) | J38: TK ANAK SALEH | K38: JL. CANDI PANGGUNG INDAH 1-3 MALANG | M38: 2257 | N38: 3205979364 | O38: 3573052305110003 | P38: 3573054105200002 | Q38: FAHMA AAFIYAH SALSABILA | R38: 1B | S38: MUTIARA | T38: AAFIYA | U38: PEREMPUAN | V38: MALANG | W38: 43952 | Y38: REGULER | AA38: ISLAM | AB38: WARGA NEGARA INDONESIA | AC38: PERUMAHAN BUMI MERANTI WANGI, JL. HOUSE OF BMW, BLOK B NO. 23. KEC. BLIMBING KEL. PANDANWANGI. JAWA TIMUR, MALANG 65124 | AD38: 03 | AE38: 013 | AF38: PANDANWANGI | AG38: BLIMBING | AH38: BLIMBING | AI38: 65124 | AJ38: KOTA MALANG | AM38: 08176671870 | AN38: 08170496931 | AO38: 5 | AP38: 4 | AS38: 13 kg | AT38: 110 cm | AV38: TIDAK | AW38: BATUK, Pilek | AX38: BAHASA INDONESIA | AY38: Arif Furqon | AZ38: 3573043110820001 | BA38: MALANG | BB38: 30255 | BC38: ISLAM | BD38: 08170496931 | BE38: S1 | BF38: PENERJEMAH | BG38: TRANSLATIONLINKER | BH38: PERUMAHAN BUMI MERANTI WANGI, JL. HOUSE OF BMW, BLOK B NO. 23. KEC. BLIMBING KEL. PANDANWANGI. JAWA TIMUR, MALANG 65124 | BI38: 08176671870 | BJ38: 50000000 | BK38: furqon@translationlinker.com | BL38: Mawar Firdausi | BM38: 3573056301870001 | BN38: MALANG | BO38: 31800 | BP38: ISLAM | BQ38: 08176671870 | BR38: S1 | BS38: PENERJEMAH | BT38: TRANSLATIONLINKER | BU38: PERUMAHAN BUMI MERANTI WANGI, JL. HOUSE OF BMW, BLOK B NO. 23. KEC. BLIMBING KEL. PANDANWANGI. JAWA TIMUR, MALANG 65124 | BV38: 08176671870 | BW38: 50000000 | BX38: mawar.firdausi@translationlinker.com
A39: 16 | I39: TAMAN KANAK-KANAK (TK) | J39: ANAK SALEH | K39: ANAK SALEH | M39: 2269 | N39: 3208860696 | O39: 3573031010130021 | P39: 3573051704200004 | Q39: IRSYAD AZKARIAN PUTRA | R39: 1B | S39: MUTIARA | T39: IRSYAD | U39: LAKI-LAKI | V39: MALANG | W39: 43938 | Y39: REGULER | AA39: ISLAM | AB39: WARGA NEGARA INDONESIA | AC39: PERUMAHAN PERMATA JINGGA WEST SIDE AREA CLUSTER ZAHARA J8 MALANG | AD39: 010 | AE39: 006 | AF39: TUNGGULWULUNG | AG39: LOWOKWARU | AH39: LOWOKWARU | AI39: 65143 | AJ39: MALANG | AM39: - | AN39: 081333212370 | AO39: 1 | AP39: - | AS39: 19 | AT39: 109 | AV39: TIDAK | AW39: BATUK, PILEK | AX39: INDONESIA | AY39: dr. DOMY PRADANA PUTRA, Sp.OT | AZ39: 3573032410890003 | BA39: NGANJUK | BB39: 32805 | BC39: ISLAM | BD39: 081333123679 | BE39: S1 | BF39: DOKTER/DOSEN | BG39: FAKULTAS KEDOKTERAN UNIVERSITAS BRAWIJAYA MALANG | BH39: JL VETERAN KETAWANGGEDE LOWOKWARU MALANG 65145 | BI39: 0341-551611 | BJ39: 5.000.000-10.000.000 | BK39: domypradanaputra@gmail.com | BL39: dr. NADINA ZERLINDA MUSTAMSIR, Sp.PD | BM39: 3573056511900005 | BN39: SURABAYA | BO39: 33202 | BP39: ISLAM | BQ39: 081333212370 | BR39: S1 | BS39: DOKTER | BT39: PERSADA HOSPITAL | BU39: JL. RADEN PANJI SUROSO KV II-IV PURWODADI BLIMBING MALANG | BV39: 0341-2996333 | BW39: 5.000.000 | BX39: nadinazerlindamustamsir90@gmail.com
A40: 38 | I40: TAMAN KANAK-KANAK (TK) | J40: TK PERTAMA IMAN 1 | K40: JL. BATU PERMATA NO. 9 TLOGOMAS | M40: 2270 | O40: 3524071608105601 | P40: 3524070601200001 | Q40: JAVAS BIRU SHANKARA EDI | R40: 1B | S40: MUTIARA | T40: JAVAS | U40: LAKI-LAKI | V40: TUBAN | W40: 43836 | Y40: REGULER | AA40: ISLAM | AB40: WARGA NEGARA INDONESIA | AC40: JALAN SIMPANG RAYA CANDI 6 PERUMAHAN DE’CLUSTER SIGURA-GURA BLOK B4 | AD40: 11 | AE40: 06 | AF40: KARANGBESUKI | AG40: SUKUN | AH40: SUKUN | AI40: 65149 | AJ40: KOTA MALANG | AM40: 082330911715 | AN40: 082330911715 | AO40: 1 | AP40: 0 | AS40: 16 kg | AT40: 110 cm | AV40: TIDAK | AW40: DEMAM | AX40: INDONESIA | AY40: Abdul Mundlir, S.pd ( sudah bercerai) | AZ40: 3523171805900001 | BA40: TUBAN | BB40: 33011 | BC40: ISLAM | BD40: 081332682212 | BE40: S1 | BF40: BAWASLU | BG40: BAWASLU | BH40: JL. PRAMUKA NO. 5 SIDOREJO, KECAMATAN TUBAN, KABUPATEN TUBAN | BI40: (0356) 8833708 | BJ40: 7.000.000 | BK40: sunahdanis63@gmail.com | BL40: Ike Danis Fatussunah, S.H.I, M.H | BM40: 3524075505930003 | BN40: TUBAN | BO40: 34104 | BP40: ISLAM | BQ40: 082330911715 | BR40: S2 | BS40: WIRASWASTA | BT40: PT ISTANA BUDIDAYA KERAPU | BU40: DESA LABUHAN, BRONDONG, LAMONGAN | BW40: 7.000.000-10.000.000 | BX40: sunahdanis63@gmail.com | BY40: Soekarno, S.H, M.H | BZ40: TUBAN | CA40: 25005 | CC40: 081332682212 | CD40: S2 | CE40: Wiraswasta
...

Sheet REPORT
A1: Data Peserta Didik SD ANAK SALEH
A2: Tapel 2026-2027
A4: Nama Kelas | C4: Kelas Terperinci | D4: LAKI-LAKI | E4: PEREMPUAN | F4: Jml Siswa @ kelas | G4: INKLUSI | H4: WALI KELAS | I4: GURU KELAS | J4: GPK | K4: GPQ
H5: Romadhoniar Fitri Aini, S.Pd.I.
A6: BERLIAN | B6: A | C6: 1A | D6: =COUNTIFS(MASTER!R:R,C6,MASTER!U:U,$D$4) -> 15 | E6: =COUNTIFS(MASTER!R:R,C6,MASTER!U:U,$E$4) -> 11 | F6: =COUNTIFS(MASTER!R:R,C6) -> 26 | G6: 2 | H6: Nadia Fatma Yanti, S.Pd | I6: Ari Iswahyudi, S.Psi | J6: Mu Ida Nur Fahilah, S.Pd -- Iinmartalivia
J7: New GPK Kolaborasi
A8: MUTIARA | B8: B | C8: 1B | D8: =COUNTIFS(MASTER!R:R,C8,MASTER!U:U,$D$4) -> 15 | E8: =COUNTIFS(MASTER!R:R,C8,MASTER!U:U,$E$4) -> 11 | F8: =COUNTIFS(MASTER!R:R,C8) -> 26 | G8: 2 | H8: Dini Eko Wulandari, S.Psi | I8: Milatun Nafisah, S.Psi | J8: Arik Wijayanto, S.Psi | K8: Azzahro Maulidiah
J9: Yetsky Yudistira, S.Or
A10: SAFIR | B10: C | C10: 1C | D10: =COUNTIFS(MASTER!R:R,C10,MASTER!U:U,$D$4) -> 15 | E10: =COUNTIFS(MASTER!R:R,C10,MASTER!U:U,$E$4) -> 10 | F10: =COUNTIFS(MASTER!R:R,C10) -> 25 | G10: 2 | H10: Gita Noviria, S.Pd | I10: Varianta Jawa Yuam Miranda, S.Pd.Gr | J10: Ika Puspitasari, S.Psi | K10: Putri Wahyuning Laili
J11: Ferdivan Andra Farerra
A12: RUBY | B12: D | C12: 1D | D12: =COUNTIFS(MASTER!R:R,C12,MASTER!U:U,$D$4) -> 15 | E12: =COUNTIFS(MASTER!R:R,C12,MASTER!U:U,$E$4) -> 10 | F12: =COUNTIFS(MASTER!R:R,C12) -> 25 | G12: 2 | H12: Irma Wahyu Putri Yoditya, S.Pd | I12: Suwaibatul Aslamiyah, A.Md.Keb., S.Pd | J12: Raga Cahya Taufikurrahman, S.Pd
J13: GPK Kolaborasi - Bu Asri
H14: Selvi Dwi Wahyuni, M.Pd
H15: Mohammad Nurahman, S.P.I., M.Pd
A17: Jml Siswa @ Level | D17: =SUM(D6:D12) -> 60 | E17: =SUM(E6:E12) -> 42 | F17: =SUM(D17:E17) -> 102 | G17: =SUM(G6:G13) -> 8
H18: Ika Wijayanti, S.AB., S.Pd
A19: GIOK | B19: A | C19: 2A | D19: =COUNTIFS(MASTER!R:R,C19,MASTER!U:U,$D$4) -> 16 | E19: =COUNTIFS(MASTER!R:R,C19,MASTER!U:U,$E$4) -> 13 | F19: =COUNTIFS(MASTER!R:R,C19) -> 29 | G19: 3 | H19: Irdayus Melindra, S.Pd | J19: Rikha Dwi Rachmawati, S.Psi | K19: Aisyah Ani Rosita, S.E
J20: Sukmawati Megawijayanti Susanto, S.Psi
J21: GPK Kolaborasi - Bu Valda
A22: PIRUS | B22: B | C22: 2B | D22: =COUNTIFS(MASTER!R:R,C22,MASTER!U:U,$D$4) -> 17 | E22: =COUNTIFS(MASTER!R:R,C22,MASTER!U:U,$E$4) -> 14 | F22: =COUNTIFS(MASTER!R:R,C22) -> 31 | G22: 4 | H22: Miftakhul Jannah, S.Pd., S.Pd.Gr | J22: Nurhayati
J23: Sherly Annisa Ramadhani
A24: AMETHYST | B24: C | C24: 2C | D24: =COUNTIFS(MASTER!R:R,C24,MASTER!U:U,$D$4) -> 15 | E24: =COUNTIFS(MASTER!R:R,C24,MASTER!U:U,$E$4) -> 14 | F24: =COUNTIFS(MASTER!R:R,C24) -> 29 | G24: 1 | H24: Aning Masyrufatin Furoida, S.Pd.I., S.Pd.Gr | J24: Nur Laili Sa'adah, S.A
A26: OPAL | B26: D | C26: 2D | D26: =COUNTIFS(MASTER!R:R,C26,MASTER!U:U,$D$4) -> 17 | E26: =COUNTIFS(MASTER!R:R,C26,MASTER!U:U,$E$4) -> 13 | F26: =COUNTIFS(MASTER!R:R,C26) -> 30 | G26: 2 | H26: Anis Amelia, S.Pd | J26: Akhmad Saiful, S.Pd | K26: Rr. Nur Apriyanti Atika Anggraini Soeharto, M.Pd
J27: GPK Kolaborasi - Bu Ayu
A30: Jml Siswa @ Level | D30: =SUM(D19:D26) -> 65 | E30: =SUM(E19:E26) -> 54 | F30: =SUM(D30:E30) -> 119 | G30: =SUM(G19:G26) -> 10
H31: Paramita Puri Anggraini, S.Pd.Gr
A32: TOPAZ | B32: A | C32: 3A | D32: =COUNTIFS(MASTER!R:R,C32,MASTER!U:U,$D$4) -> 15 | E32: =COUNTIFS(MASTER!R:R,C32,MASTER!U:U,$E$4) -> 12 | F32: =COUNTIFS(MASTER!R:R,C32) -> 27 | G32: 2 | H32: Ika Su'udia, S.Si.Gr | J32: Nurul Asri Fitriyah | K32: Sukma Abdul Rozy
A33: AQUAMARINE | B33: B | C33: 3B | D33: =COUNTIFS(MASTER!R:R,C33,MASTER!U:U,$D$4) -> 16 | E33: =COUNTIFS(MASTER!R:R,C33,MASTER!U:U,$E$4) -> 11 | F33: =COUNTIFS(MASTER!R:R,C33) -> 27 | G33: 2 | H33: Hj. Noor Jeehan, S.Ag., M.Pd.I | J33: Desilfa Dwi Nursavitri, S.Psi | K33: Hurul Jinani, S.Pd
A34: OBSIDIAN | B34: C | C34: 3C | D34: =COUNTIFS(MASTER!R:R,C34,MASTER!U:U,$D$4) -> 16 | E34: =COUNTIFS(MASTER!R:R,C34,MASTER!U:U,$E$4) -> 12 | F34: =COUNTIFS(MASTER!R:R,C34) -> 28 | G34: 2 | H34: Arif Nur Rahman, S.S., M.Pd.Gr | J34: Afriska Nur Azizah, S.Pd
A35: ZAMRUD | B35: D | C35: 3D | D35: =COUNTIFS(MASTER!R:R,C35,MASTER!U:U,$D$4) -> 16 | E35: =COUNTIFS(MASTER!R:R,C35,MASTER!U:U,$E$4) -> 11 | F35: =COUNTIFS(MASTER!R:R,C35) -> 27 | G35: 2 | H35: Desty Ariani Mutiara, S.Pd., S.Pd | J35: M. Baha'ul Alamsyah Al Faini, S.Pd
H36: Prima Suci Ibar Wati Ningrum, S.Or., M.Pd
A38: Jml Siswa @ Level | D38: =SUM(D32:D37) -> 63 | E38: =SUM(E32:E37) -> 46 | F38: =SUM(D38:E38) -> 109 | G38: =SUM(G32:G35) -> 8
H39: Nur Risky Marsa Romadhona, S.Pd., S.Pd.Gr
A40: JASPER | B40: A | C40: 4A | D40: =COUNTIFS(MASTER!R:R,C40,MASTER!U:U,$D$4) -> 17 | E40: =COUNTIFS(MASTER!R:R,C40,MASTER!U:U,$E$4) -> 13 | F40: =COUNTIFS(MASTER!R:R,C40) -> 30 | G40: 0 | H40: Miftakul Jannah, S.Pd | I40: Risas Wahyudi, S.Pd. | K40: Muhammad Akbar Amin, S.Pd.Gr
A41: MALASIT | B41: B | C41: 4B | D41: =COUNTIFS(MASTER!R:R,C41,MASTER!U:U,$D$4) -> 16 | E41: =COUNTIFS(MASTER!R:R,C41,MASTER!U:U,$E$4) -> 13 | F41: =COUNTIFS(MASTER!R:R,C41) -> 29 | G41: 1 | H41: Ucik Sriwahyuni, S.Pd | I41: Masruhan, S.Pd.I., M.Pd | J41: Kofifah Indar Khoiroh, S.Psi
A42: GARNET | B42: C | C42: 4C | D42: =COUNTIFS(MASTER!R:R,C42,MASTER!U:U,$D$4) -> 18 | E42: =COUNTIFS(MASTER!R:R,C42,MASTER!U:U,$E$4) -> 12 | F42: =COUNTIFS(MASTER!R:R,C42) -> 30 | G42: 2 | H42: Sri Subakti, S.Pd.SD.Gr | J42: Nila Fadilah, S.Pd | K42: Yusuf Mu'awiyah, S.TP
A43: CITRINE
B44: D | C44: 4D | D44: =COUNTIFS(MASTER!R:R,C44,MASTER!U:U,$D$4) -> 17 | E44: =COUNTIFS(MASTER!R:R,C44,MASTER!U:U,$E$4) -> 13 | F44: =COUNTIFS(MASTER!R:R,C44) -> 30 | G44: 0 | H44: Lailatul Munawaroh, S.Pd., M.Pd | K44: Nabila Ucinanda Betarizqy, S.Pd
A46: Jml Siswa @ Level | D46: =SUM(D40:D45) -> 68 | E46: =SUM(E40:E45) -> 51 | F46: =SUM(D46:E46) -> 119 | G46: =SUM(G40:G44) -> 3
H47: Kusnia, S.Pd.I
...

Sheet Lembar2
